# ?Async/await

### `Async`

Начнём с ключевого слова `async`. Оно ставится перед функцией, вот так:

~~~
async function f() {
  return 1;
}
~~~

У слова `async` один простой смысл: эта функция всегда возвращает промис. Значения других типов оборачиваются в завершившийся успешно промис автоматически.

Например, эта функция возвратит выполненный промис с результатом 1:

~~~
async function f() {
  return 1;
}

f().then(console.log); // 1
~~~

Можно и явно вернуть промис, результат будет одинаковым:

~~~
async function f() {
  return Promise.resolve(1);
}

f().then(console.log); // 1
~~~

Так что ключевое слово `async` перед функцией гарантирует, что эта функция в любом случае вернёт промис. Согласитесь, достаточно просто? Но это ещё не всё. Есть другое ключевое слово – `await`, которое можно использовать только внутри `async`-функций.

### `Await`

Синтаксис:

~~~
// работает только внутри async–функций
const value = await promise;
~~~

Ключевое слово `await` заставит интерпретатор JavaScript ждать до тех пор, пока промис справа от `await` не выполнится. После чего оно вернёт его результат, и выполнение кода продолжится.

В этом примере промис успешно выполнится через 1 секунду:

~~~
async function f() {
  const promise = new Promise((resolve, reject) => {
    setTimeout(() => resolve("Готово!"), 1000);
  });

  const result = await promise; // будет ждать, пока промис не выполнится (*)

  console.log(result); // "Готово!"
}

f();
~~~

В данном примере выполнение функции остановится на строке `(*)` до тех пор, пока промис не выполнится. Это произойдёт через секунду после запуска функции. После чего в переменную `result` будет записан результат выполнения промиса, и браузер отобразит «Готово!».

Обратите внимание, хотя `await` и заставляет JavaScript дожидаться выполнения промиса, это не отнимает ресурсов процессора. Пока промис не выполнится, JS-движок может заниматься другими задачами: выполнять прочие скрипты, обрабатывать события и т.п.

По сути, это просто «синтаксический сахар» для получения результата промиса, более наглядный, чем `promise.then`.

##### `await` нельзя использовать в обычных функциях

Если мы попробуем использовать `await` внутри функции, объявленной без `async`, получим синтаксическую ошибку:

~~~
function f() {
  const promise = Promise.resolve(1);
  const result = await promise; // SyntaxError
}
~~~

Ошибки не будет, если мы укажем ключевое слово `async` перед объявлением функции. Как было сказано раньше, `await` можно использовать только внутри `async`–функций.

Давайте рассмотрим `showAvatar()` с `async`/`await`:

~~~
async function showAvatar() {
  // запрашиваем JSON с данными пользователя
  const response = await fetch("/article/promise-chaining/user.json");
  const user = await response.json();

  // запрашиваем информацию об этом пользователе из github
  const githubResponse = await fetch(`https://api.github.com/users/${user.name}`);
  const githubUser = await githubResponse.json();

  // отображаем аватар пользователя
  const img = document.createElement("img");
  img.src = githubUser.avatar_url;
  img.className = "promise-avatar-example";
  document.body.append(img);

  // ждём 3 секунды и затем скрываем аватар
  await new Promise((resolve, reject) => setTimeout(resolve, 3000));

  img.remove();

  return githubUser;
}

showAvatar();
~~~

Получилось очень просто и читаемо.

##### `await` нельзя использовать на верхнем уровне вложенности

`await` работает только внутри `async`–функций, так что так сделать не получится:

~~~
// SyntaxError на верхнем уровне вложенности
const response = await fetch('/article/promise-chaining/user.json');
const user = await response.json();
~~~

Можно обернуть этот код в анонимную `async`–функцию, тогда всё заработает:

~~~
(async () => {
  const response = await fetch('/article/promise-chaining/user.json');
  const user = await response.json();
})();
~~~

##### `await` работает с «thenable»–объектами

Как и `promise.then`, `await` позволяет работать с промис–совместимыми объектами. Идея в том, что если у объекта можно вызвать метод `then`, этого достаточно, чтобы использовать его с `await`.

В примере ниже, экземпляры класса `Thenable` будут работать вместе с `await`:

~~~
class Thenable {
  constructor(num) {
    this.num = num;
  }

  then(resolve, reject) {
    // выполнить resolve со значением this.num * 2 через 1000мс
    setTimeout(() => resolve(this.num * 2), 1000); // (*)
  }
}

async function f() {
  // код будет ждать 1 секунду,
  // после чего значение result станет равным 2
  const result = await new Thenable(1);
  console.log(result);
}

f();
~~~

Когда `await` получает объект с `.then`, не являющийся промисом, JavaScript автоматически запускает этот метод, передавая ему аргументы – встроенные функции `resolve` и `reject`. Затем `await` приостановит дальнейшее выполнение кода, пока любая из этих функций не будет вызвана (в примере это строка `(*)`). После чего выполнение кода продолжится с результатом `resolve` или `reject` соответственно.

##### Асинхронные методы классов

Для объявления асинхронного метода достаточно написать `async` перед именем:

~~~
class Waiter {
  async wait() {
    return await Promise.resolve(1);
  }
}

new Waiter().wait().then(console.log); // 1
~~~

Как и в случае с асинхронными функциями, такой метод гарантированно возвращает промис, и в его теле можно использовать `await`.

### Обработка ошибок

Когда промис завершается успешно, `await promise` возвращает результат. Когда завершается с ошибкой – будет выброшено исключение. Как если бы на этом месте находилось выражение `throw`.

Такой код:

~~~
async function f() {
  await Promise.reject(new Error("Упс!"));
}

f(); // Uncaught Error Error: Упс!
~~~

Делает то же самое, что и такой:

~~~
async function f() {
  throw new Error("Упс!");
}

f(); // Uncaught Error Error: Упс!
~~~

Но есть отличие: на практике промис может завершиться с ошибкой не сразу, а через некоторое время. В этом случае будет задержка, а затем `await` выбросит исключение.

Такие ошибки можно ловить, используя `try..catch`, как с обычным `throw`:

~~~
async function f() {
  try {
    const response = await fetch("http://no-such-url");
  } catch (err) {
    console.log(err); // TypeError: failed to fetch
  }
}

f();
~~~

В случае ошибки выполнение `try` прерывается и управление прыгает в начало блока `catch`. Блоком `try` можно обернуть несколько строк:

~~~
async function f() {
  try {
    const response = await fetch("/no-user-here");
    const user = await response.json();
  } catch (err) {
    // перехватит любую ошибку в блоке try: и в fetch, и в response.json
    console.log(err);
  }
}

f();
~~~

Если у нас нет `try..catch`, асинхронная функция будет возвращать завершившийся с ошибкой промис (в состоянии `rejected`). В этом случае мы можем использовать метод `.catch` промиса, чтобы обработать ошибку:

~~~
async function f() {
  const response = await fetch("http://no-such-url");
}

// f() вернёт промис в состоянии rejected
f().catch(console.log); // TypeError: failed to fetch // (*)
~~~

Если забыть добавить `.catch`, то будет сгенерирована ошибка «Uncaught promise error» и информация об этом будет выведена в консоль. Такие ошибки можно поймать глобальным обработчиком.

##### `async`/`await` и `promise.then`/`catch`

При работе с `async`/`await`, `.then` используется нечасто, так как `await` автоматически ожидает завершения выполнения промиса. В этом случае обычно (но не всегда) гораздо удобнее перехватывать ошибки, используя `try..catch`, нежели чем `.catch`.

Но на верхнем уровне вложенности (вне `async`–функций) `await` использовать нельзя, поэтому `.then`/`catch` для обработки финального результата или ошибок – обычная практика.

Так сделано в строке `(*)` в примере выше.

##### `async`/`await` отлично работает с `Promise.all`

Когда необходимо подождать несколько промисов одновременно, можно обернуть их в `Promise.all`, и затем `await`:

~~~
// await будет ждать массив с результатами выполнения всех промисов
const results = await Promise.all([
  fetch(url1),
  fetch(url2),
  // ...
]);
~~~

В случае ошибки она будет передаваться как обычно: от завершившегося с ошибкой промиса к `Promise.all`. А после будет сгенерировано исключение, которое можно отловить, обернув выражение в `try..catch`.
